Traceback (most recent call last):
  File "D:\cedri\anaconda3\envs\prepa\lib\site-packages\jupyter_cache\executors\utils.py", line 51, in single_nb_execution
    executenb(
  File "D:\cedri\anaconda3\envs\prepa\lib\site-packages\nbclient\client.py", line 1204, in execute
    return NotebookClient(nb=nb, resources=resources, km=km, **kwargs).execute()
  File "D:\cedri\anaconda3\envs\prepa\lib\site-packages\nbclient\util.py", line 84, in wrapped
    return just_run(coro(*args, **kwargs))
  File "D:\cedri\anaconda3\envs\prepa\lib\site-packages\nbclient\util.py", line 62, in just_run
    return loop.run_until_complete(coro)
  File "D:\cedri\anaconda3\envs\prepa\lib\asyncio\base_events.py", line 647, in run_until_complete
    return future.result()
  File "D:\cedri\anaconda3\envs\prepa\lib\site-packages\nbclient\client.py", line 663, in async_execute
    await self.async_execute_cell(
  File "D:\cedri\anaconda3\envs\prepa\lib\site-packages\nbclient\client.py", line 965, in async_execute_cell
    await self._check_raise_for_error(cell, cell_index, exec_reply)
  File "D:\cedri\anaconda3\envs\prepa\lib\site-packages\nbclient\client.py", line 862, in _check_raise_for_error
    raise CellExecutionError.from_cell_and_msg(cell, exec_reply_content)
nbclient.exceptions.CellExecutionError: An error occurred while executing the following cell:
------------------
def Esource(t):
    E0 = 2
    freq = 50
    return E0 * np.cos(2 * np.pi * freq * t)

def iThevenin(u):
    """Pour obtenir i Ã  partir de u"""
    R = 50
    return (E - u) / R

N = 1000
freq = 50
R = 50
tk = np.linspace(0, 2 / freq, N)
Ek = Esource(tk)

uk = []
ik = []
for E in Ek:
    uk.append(bisect(f, -3, 3))
    ik.append(iThevenin(uk[-1]))

fig1, ax = plt.subplots()
ax.set_xlabel('t(s)')
ax.set_ylabel('u(V)')
ax.plot(tk, uk)
ax.grid()

fig2, ax = plt.subplots()
ax.set_xlabel('t(s)')
ax.set_ylabel('i(A)')
ax.plot(tk, R * ik)
ax.grid()
------------------

[1;31m---------------------------------------------------------------------------[0m
[1;31mValueError[0m                                Traceback (most recent call last)
Cell [1;32mIn [3], line 32[0m
[0;32m     30[0m ax[38;5;241m.[39mset_xlabel([38;5;124m'[39m[38;5;124mt(s)[39m[38;5;124m'[39m)
[0;32m     31[0m ax[38;5;241m.[39mset_ylabel([38;5;124m'[39m[38;5;124mi(A)[39m[38;5;124m'[39m)
[1;32m---> 32[0m [43max[49m[38;5;241;43m.[39;49m[43mplot[49m[43m([49m[43mtk[49m[43m,[49m[43m [49m[43mR[49m[43m [49m[38;5;241;43m*[39;49m[43m [49m[43mik[49m[43m)[49m
[0;32m     33[0m ax[38;5;241m.[39mgrid()

File [1;32mD:\cedri\anaconda3\envs\prepa\lib\site-packages\matplotlib\axes\_axes.py:1662[0m, in [0;36mAxes.plot[1;34m(self, scalex, scaley, data, *args, **kwargs)[0m
[0;32m   1419[0m [38;5;124;03m"""[39;00m
[0;32m   1420[0m [38;5;124;03mPlot y versus x as lines and/or markers.[39;00m
[0;32m   1421[0m 
[1;32m   (...)[0m
[0;32m   1659[0m [38;5;124;03m(``'green'``) or hex strings (``'#008000'``).[39;00m
[0;32m   1660[0m [38;5;124;03m"""[39;00m
[0;32m   1661[0m kwargs [38;5;241m=[39m cbook[38;5;241m.[39mnormalize_kwargs(kwargs, mlines[38;5;241m.[39mLine2D)
[1;32m-> 1662[0m lines [38;5;241m=[39m [[38;5;241m*[39m[38;5;28mself[39m[38;5;241m.[39m_get_lines([38;5;241m*[39margs, data[38;5;241m=[39mdata, [38;5;241m*[39m[38;5;241m*[39mkwargs)]
[0;32m   1663[0m [38;5;28;01mfor[39;00m line [38;5;129;01min[39;00m lines:
[0;32m   1664[0m     [38;5;28mself[39m[38;5;241m.[39madd_line(line)

File [1;32mD:\cedri\anaconda3\envs\prepa\lib\site-packages\matplotlib\axes\_base.py:311[0m, in [0;36m_process_plot_var_args.__call__[1;34m(self, data, *args, **kwargs)[0m
[0;32m    309[0m     this [38;5;241m+[39m[38;5;241m=[39m args[[38;5;241m0[39m],
[0;32m    310[0m     args [38;5;241m=[39m args[[38;5;241m1[39m:]
[1;32m--> 311[0m [38;5;28;01myield from[39;00m [38;5;28;43mself[39;49m[38;5;241;43m.[39;49m[43m_plot_args[49m[43m([49m
[0;32m    312[0m [43m    [49m[43mthis[49m[43m,[49m[43m [49m[43mkwargs[49m[43m,[49m[43m [49m[43mambiguous_fmt_datakey[49m[38;5;241;43m=[39;49m[43mambiguous_fmt_datakey[49m[43m)[49m

File [1;32mD:\cedri\anaconda3\envs\prepa\lib\site-packages\matplotlib\axes\_base.py:504[0m, in [0;36m_process_plot_var_args._plot_args[1;34m(self, tup, kwargs, return_kwargs, ambiguous_fmt_datakey)[0m
[0;32m    501[0m     [38;5;28mself[39m[38;5;241m.[39maxes[38;5;241m.[39myaxis[38;5;241m.[39mupdate_units(y)
[0;32m    503[0m [38;5;28;01mif[39;00m x[38;5;241m.[39mshape[[38;5;241m0[39m] [38;5;241m!=[39m y[38;5;241m.[39mshape[[38;5;241m0[39m]:
[1;32m--> 504[0m     [38;5;28;01mraise[39;00m [38;5;167;01mValueError[39;00m([38;5;124mf[39m[38;5;124m"[39m[38;5;124mx and y must have same first dimension, but [39m[38;5;124m"[39m
[0;32m    505[0m                      [38;5;124mf[39m[38;5;124m"[39m[38;5;124mhave shapes [39m[38;5;132;01m{[39;00mx[38;5;241m.[39mshape[38;5;132;01m}[39;00m[38;5;124m and [39m[38;5;132;01m{[39;00my[38;5;241m.[39mshape[38;5;132;01m}[39;00m[38;5;124m"[39m)
[0;32m    506[0m [38;5;28;01mif[39;00m x[38;5;241m.[39mndim [38;5;241m>[39m [38;5;241m2[39m [38;5;129;01mor[39;00m y[38;5;241m.[39mndim [38;5;241m>[39m [38;5;241m2[39m:
[0;32m    507[0m     [38;5;28;01mraise[39;00m [38;5;167;01mValueError[39;00m([38;5;124mf[39m[38;5;124m"[39m[38;5;124mx and y can be no greater than 2D, but have [39m[38;5;124m"[39m
[0;32m    508[0m                      [38;5;124mf[39m[38;5;124m"[39m[38;5;124mshapes [39m[38;5;132;01m{[39;00mx[38;5;241m.[39mshape[38;5;132;01m}[39;00m[38;5;124m and [39m[38;5;132;01m{[39;00my[38;5;241m.[39mshape[38;5;132;01m}[39;00m[38;5;124m"[39m)

[1;31mValueError[0m: x and y must have same first dimension, but have shapes (1000,) and (50000,)
ValueError: x and y must have same first dimension, but have shapes (1000,) and (50000,)

